<!-- Author: Jack Cooperman
Claude AI was used to help debug issues and provide inertia values to make movement most realistic. -->

<?xml version="1.0"?>
<robot name="Phil">
    <material name="blue">
        <color rgba="0.0 0.0 1.0 1.0"/>
    </material>
    <material name="red">
        <color rgba="1.0 0.0 0.0 1.0"/>
    </material>
        <material name="black">
        <color rgba="0.0 0.0 0.0 1.0"/>
    </material>
    
    <link name="base_link">
        <inertial>
            <mass value="0.0001"/>
            <inertia ixx="0.0001" ixy="0" ixz="0" iyy="0.0001" iyz="0" izz="0.0001"/>
        </inertial>
    </link>

    <link name="axle">
        <visual>
            <geometry>
                <cylinder length="0.8" radius="0.1"/>
            </geometry>
            <origin xyz="0.0 0.0 0.0" rpy="0.0 1.5708 0.0"/>
            <material name="red"/>
        </visual>
        <collision>
            <geometry>
                <cylinder length="0.8" radius="0.1"/>
            </geometry>
            <origin xyz="0.0 0.0 0.0" rpy="0.0 1.5708 0.0"/>
        </collision>
        <inertial>
            <mass value="1.0"/>
            <inertia ixx="0.056" ixy="0" ixz="0" iyy="0.054" iyz="0" izz="0.005"/>
        </inertial>
    </link>

    <joint name="base_to_axle" type="fixed">
        <parent link="base_link"/>
        <child link="axle"/>
        <origin xyz="0 0 0.4"/>
    </joint>

    <link name="left_wheel">
        <visual>
            <geometry>
                <sphere radius="0.4"/>
            </geometry>
            <material name="blue"/>
        </visual>
        <collision>
            <geometry>
                <sphere radius="0.4"/>
            </geometry>
        </collision>
        <inertial>
            <mass value="1.0"/>
            <inertia ixx="0.064" ixy="0" ixz="0" iyy="0.064" iyz="0" izz="0.064"/>
        </inertial>
    </link>

    <link name="right_wheel">
        <visual>
            <geometry>
                <sphere radius="0.4"/>
            </geometry>
            <material name="blue"/>
        </visual>
        <collision>
            <geometry>
                <sphere radius="0.4"/>
            </geometry>
        </collision>
        <inertial>
            <mass value="1.0"/>
            <inertia ixx="0.064" ixy="0" ixz="0" iyy="0.064" iyz="0" izz="0.064"/>
        </inertial>
    </link>

    <joint name="axle_left_joint" type="continuous">
        <parent link="axle"/>
        <child link="left_wheel"/>
        <origin xyz="0.8 0.0 0.0" rpy="0 0 0"/>
        <axis xyz="0 1 0"/>
    </joint>

    <joint name="axle_right_joint" type="continuous">
        <parent link="axle"/>
        <child link="right_wheel"/>
        <origin xyz="-0.8 0.0 0" rpy="0 0.0 0.0"/>
        <axis xyz="0 1 0"/>
    </joint>
</robot>